Workbook

Sheet README
A1: Generic apixaban vs warfarin for stroke prevention in non-valvular AF — cost-utility & budget impact model
A2: Author: Daniel Pazos Cordero (portfolio project, October 2026). Not affiliated with or endorsed by CDA-AMC.
A4: PURPOSE
A5: Re-runs the CADTH 4th-edition guidelines worked example (DOACs vs warfarin, CHADS2 = 2) with 2026 Ontario generic apixaban prices,
A6: to ask whether generic entry changes the value proposition for public drug plans. Includes a 3-year Ontario budget impact analysis.
A8: COLOUR LEGEND
A9: Blue text = hard-coded input (sourced in the Inputs sheet). Black text = formula. Green text = link to another sheet.
A10: Yellow fill = key decision lever (drug price, perspective inputs, budget-impact assumptions). Change these to run your own scenarios.
A12: SHEETS
A13: Inputs — every parameter, base value, one-way range, PSA distribution and source. Each base value has a defined name used in formulas.
A14: LifeTable — Statistics Canada 2021-2023 anchors and the Gompertz fit used for age-specific background mortality.
A15: Apixaban / Warfarin — cohort Markov traces: 120 three-month cycles (age 70 to 100). Identical formulas; only the arm flag in cell B2 differs.
... A28: the Excel deterministic results match Python to the cent (see Validation).

Sheet Inputs
A1: Parameter | B1: Name (used in formulas) | C1: Base value | D1: Low (OWSA) | E1: High (OWSA) | F1: PSA distribution | G1: Source / note
A2: Model settings
A3: Start age (years) | B3: start_age | C3: 70 | G3: CHADS2 = 2 cohort; CADTH worked example
A4: Reference age for trial-based rates | B4: ref_age | C4: 70 | G4: Age at which RE-LY-based rates apply
A5: Cycle length (years) | B5: dt | C5: 0.25 | G5: 3-month cycles, as in CADTH worked example
A6: Discount rate (costs and QALYs) | B6: disc_rate | C6: 0.015 | G6: CADTH 4th ed. reference case
A7: Willingness to pay ($/QALY) | B7: wtp | C7: 50000 | G7: Threshold used in CADTH worked example for NMB
A8: Apixaban effect waning: start (years) | B8: wane_start | C8: 2 | G8: Scenario lever (CADTH worked example scenario)
A9: Apixaban effect waning: annual decay | B9: wane_decay | C9: 0 | G9: 0 = no waning (reference case); 0.05 = CADTH scenario
A10: Validation mode (1 = CADTH 2011 prices, 0 = 2025 reference case) | B10: val_mode | C10: 0 | G10: Switch to 1 to reproduce the CADTH worked example at 2011 prices (see Validation sheet)
A11: Price year adjustment
A12: CPI 2011 (2002 = 100) | B12: cpi_2011 | C12: 119.9 | G12: Statistics Canada Table 18-10-0005-01
A13: CPI 2025 (2002 = 100) | B13: cpi_2025 | C13: 164.2 | G13: Statistics Canada Table 18-10-0005-01, annual average
A14: Inflator 2011 to 2025 | B14: inflate | C14: =IF(val_mode=1,1,cpi_2025/cpi_2011) -> 1.3694746 | G14: Formula (= 1 in validation mode, i.e. costs stay in 2011 CAD)
A15: Drug prices (ODB, per tablet) and annual drug costs
A16: Apixaban 5 mg price per tablet | B16: apx_price_tab | C16: 0.4084 | G16: ODB Formulary, generic apixaban 5 mg, accessed Oct 2026. Brand Eliquis = $1.6336 (enter it here for the brand scenario).
A17: Apixaban annual cost in 2011 (validation mode only) | B17: c_apixaban_2011 | C17: 1289.44 | G17: CADTH worked example, brand apixaban 2011 ODB price
A18: Days per year | B18: days_yr | C18: 365.25 | G18: CDA-AMC convention for annualising daily drug costs
A19: Apixaban 5 mg BID, annual | B19: c_apixaban | C19: =IF(val_mode=1,c_apixaban_2011,apx_price_tab*2*days_yr) -> 298.3362 | G19: Formula
A20: Warfarin 5 mg daily, annual | B20: c_warfarin | C20: 54.61 | D20: 27 | E20: 110 | F20: Fixed | G20: CADTH worked example (2011 ODB). Not inflated: generic prices have not tracked CPI. VERIFY against current ODB listing.
A21: INR monitoring, annual (warfarin only) | B21: c_inr_2011 | C21: 240.69 | G21: CADTH worked example (from HQO 2009), 2011 CAD
A22: INR monitoring, annual, 2025 CAD | B22: c_inr | C22: =c_inr_2011*inflate -> 329.61883 | D22: =0.5*c_inr_2011*inflate -> 164.80942 | E22: =1.5*c_inr_2011*inflate -> 494.42825 | F22: Fixed | G22: Formula: 2011 value x CPI inflator
A23: Aspirin, annual | B23: c_aspirin | C23: 39.04 | D23: 20 | E23: 60 | F23: Fixed | G23: CADTH worked example (2011 ODB), not inflated
A24: Background mortality
A25: Non-vascular death at age 70 (annual) | B25: p_nonvasc_death | C25: 0.033 | D25: 0.025 | E25: 0.041 | F25: Beta (mean = base, n = 11,794) | G25: RE-LY warfarin arm via CADTH worked example; scaled by age with the StatCan life-table gradient (LifeTable sheet)
A26: Mortality after stroke | B26: hr_death_prior_stroke | C26: 2.3 | D26: 2 | E26: 2.7 | F26: Lognormal (95% CI 2.0-2.7) | G26: CADTH 2017 worked example, Table 1 (from Coyle et al. 2013)
A27: Baseline annual event probabilities on warfarin (CHADS2 = 2)
A28: Stroke rate on warfarin (annual) | B28: p_stroke | C28: 0.016 | D28: 0.012 | E28: 0.02 | F28: Beta (mean = base, n = 11,794) | G28: CADTH 2017 worked example, Table 1 (from Coyle et al. 2013)
A29: TIA rate (annual) | B29: p_tia | C29: 0.008 | D29: 0.006 | E29: 0.01 | F29: Beta (mean = base, n = 11,794) | G29: CADTH 2017 worked example, Table 1 (from Coyle et al. 2013)
A30: ICH rate on warfarin (annual) | B30: p_ich | C30: 0.008 | D30: 0.006 | E30: 0.01 | F30: Beta (mean = base, n = 11,794) | G30: CADTH 2017 worked example, Table 1 (from Coyle et al. 2013)
A31: Major bleed rate on warfarin (annual) | B31: p_major_bleed | C31: 0.033 | D31: 0.025 | E31: 0.041 | F31: Beta (mean = base, n = 11,794) | G31: CADTH 2017 worked example, Table 1 (from Coyle et al. 2013)
A32: Minor bleed rate (annual) | B32: p_minor_bleed | C32: 0.164 | D32: 0.123 | E32: 0.205 | F32: Beta (mean = base, n = 11,794) | G32: CADTH 2017 worked example, Table 1 (from Coyle et al. 2013)
A33: MI rate (annual) | B33: p_mi | C33: 0.006 | D33: 0.0045 | E33: 0.0075 | F33: Beta (mean = base, n = 11,794) | G33: CADTH 2017 worked example, Table 1 (from Coyle et al. 2013)
A34: Event outcomes
A35: Proportion of first strokes fatal | B35: f_stroke_fatal | C35: 0.237 | D35: 0.18 | E35: 0.3 | F35: Beta (mean = base, n = 186) | G35: CADTH 2017 worked example, Table 1 (from Coyle et al. 2013)
A36: Proportion of non-fatal strokes major | B36: f_stroke_major | C36: 0.333 | D36: 0.25 | E36: 0.42 | F36: Beta (mean = base, n = 117) | G36: CADTH 2017 worked example, Table 1 (from Coyle et al. 2013)
A37: Increase in fatality of recurrent stroke | B37: hr_recur_fatal | C37: 1.57 | D37: 1.21 | E37: 2.03 | F37: Lognormal (95% CI 1.21-2.03) | G37: CADTH 2017 worked example, Table 1 (from Coyle et al. 2013)
A38: Proportion of major bleeds / ICH fatal | B38: f_bleed_fatal | C38: 0.084 | D38: 0.06 | E38: 0.11 | F38: Beta (mean = base, n = 476) | G38: CADTH 2017 worked example, Table 1 (from Coyle et al. 2013)
A39: Proportion of MIs fatal | B39: f_mi_fatal | C39: 0.121 | D39: 0.06 | E39: 0.2 | F39: Beta (mean = base, n = 66) | G39: CADTH 2017 worked example, Table 1 (from Coyle et al. 2013)
A40: Risk modifiers
...

Sheet Results
A1: Reference-case results — generic apixaban vs warfarin, CHADS2 = 2, age 70, lifetime, 2025 CAD
A3: Outcome (per patient) | B3: Apixaban (generic) | C3: Warfarin | D3: Incremental
A4: Total cost (discounted) | B4: =SUM(Apixaban!DT6:DT125) -> 22807.847 | C4: =SUM(Warfarin!DT6:DT125) -> 28415.756 | D4: =B4-C4 -> -5607.9085
A5: Drug and monitoring costs | B5: =SUM(Apixaban!DU6:DU125) -> 2362.0973 | C5: =SUM(Warfarin!DU6:DU125) -> 2791.2029 | D5: =B5-C5 -> -429.10568
A6: Clinical event costs | B6: =SUM(Apixaban!DV6:DV125) -> 11499.738 | C6: =SUM(Warfarin!DV6:DV125) -> 13952.852 | D6: =B6-C6 -> -2453.1141
A7: Long-term post-event costs | B7: =SUM(Apixaban!DW6:DW125) -> 8946.0119 | C7: =SUM(Warfarin!DW6:DW125) -> 11671.701 | D7: =B7-C7 -> -2725.6887
A8: QALYs (discounted) | B8: =SUM(Apixaban!DX6:DX125) -> 7.4644651 | C8: =SUM(Warfarin!DX6:DX125) -> 7.2281947 | D8: =B8-C8 -> 0.2362704
A9: Life-years (discounted) | B9: =SUM(Apixaban!DY6:DY125) -> 9.3878909 | C9: =SUM(Warfarin!DY6:DY125) -> 9.1294309 | D9: =B9-C9 -> 0.25846001
A10: Total cost (undiscounted) | B10: =SUM(Apixaban!DQ6:DQ125) -> 25757.486 | C10: =SUM(Warfarin!DQ6:DQ125) -> 31951.543 | D10: =B10-C10 -> -6194.058
A11: QALYs (undiscounted) | B11: =SUM(Apixaban!DR6:DR125) -> 8.2250407 | C11: =SUM(Warfarin!DR6:DR125) -> 7.9444876 | D11: =B11-C11 -> 0.28055307
A12: Life-years (undiscounted) | B12: =SUM(Apixaban!DS6:DS125) -> 10.352352 | C12: =SUM(Warfarin!DS6:DS125) -> 10.04332 | D12: =B12-C12 -> 0.30903264
A13: Strokes per 1,000 patients | B13: =SUM(Apixaban!DZ6:DZ125)*1000 -> 238.60513 | C13: =SUM(Warfarin!DZ6:DZ125)*1000 -> 281.7505 | D13: =B13-C13 -> -43.14537
A14: Intracranial haemorrhages per 1,000 | B14: =SUM(Apixaban!EA6:EA125)*1000 -> 35.5206 | C14: =SUM(Warfarin!EA6:EA125)*1000 -> 69.803287 | D14: =B14-C14 -> -34.282686
A15: Major bleeds per 1,000 | B15: =SUM(Apixaban!EB6:EB125)*1000 -> 292.37459 | C15: =SUM(Warfarin!EB6:EB125)*1000 -> 338.92992 | D15: =B15-C15 -> -46.555331
A17: ICER ($ per QALY gained) | D17: =IF(AND(D4<=0,D8>=0),"Apixaban dominant",IF(AND(D4>=0,D8<=0),"Apixaban dominated",D4/D8)) -> Apixaban dominant
A18: Incremental net monetary benefit at WTP | D18: =D8*wtp-D4 -> 17421.428
A20: Price threshold analysis (apixaban 5 mg, per tablet)
A21: Current ODB price per tablet | D21: =apx_price_tab -> 0.4084
A22: Discounted years on anticoagulant (apixaban arm) | D22: =SUM(Apixaban!EC6:EC125) -> 7.6961946
A23: Price at which apixaban is cost-neutral vs warfarin | D23: =D21-D4/(D22*2*days_yr) -> 1.4058811
A24: Price at which ICER = WTP | D24: =D21+(D8*wtp-D4)/(D22*2*days_yr) -> 3.5071569
A25: Note: incremental cost is linear in the apixaban price, so these thresholds are exact.
A27: Per-patient undiscounted total cost by year (feeds BIA)
A28: Year 1 | B28: =SUM(Apixaban!DQ6:DQ9) -> 1218.836 | C28: =SUM(Warfarin!DQ6:DQ9) -> 1607.397 | D28: =B28-C28 -> -388.56099
A29: Year 2 | B29: =SUM(Apixaban!DQ10:DQ13) -> 1388.8403 | C29: =SUM(Warfarin!DQ10:DQ13) -> 1833.5169 | D29: =B29-C29 -> -444.67654
A30: Year 3 | B30: =SUM(Apixaban!DQ14:DQ17) -> 1533.6424 | C30: =SUM(Warfarin!DQ14:DQ17) -> 2019.0885 | D30: =B30-C30 -> -485.44606

Sheet Validation
A1: Validation
A2: Status cells read PASS or CHECK. No IFERROR is used anywhere, so any error value that appears is a genuine error.
A4: A. Mass balance (each cycle's state occupancy must sum to 1) | B4: Minimum | C4: Maximum | D4: Status
A5: Apixaban sheet | B5: =MIN(Apixaban!DM6:DM125) -> 1 | C5: =MAX(Apixaban!DM6:DM125) -> 1 | D5: =IF(AND(ABS(B5-1)<0.000000001,ABS(C5-1)<0.000000001),"PASS","CHECK") -> PASS
A6: Warfarin sheet | B6: =MIN(Warfarin!DM6:DM125) -> 1 | C6: =MAX(Warfarin!DM6:DM125) -> 1 | D6: =IF(AND(ABS(B6-1)<0.000000001,ABS(C6-1)<0.000000001),"PASS","CHECK") -> PASS
A8: B. Excel vs Python (expected values switch with val_mode) | B8: Excel (live) | C8: Python | D8: Difference | E8: Status
A9: Apixaban: total cost (discounted) | B9: =Results!B4 -> 22807.847 | C9: =IF(val_mode=1,24919.455929835,22807.8471211961) -> 22807.847 | D9: =B9-C9 -> 0 | E9: =IF(ABS(D9)<0.01,"PASS","CHECK") -> PASS
A10: Warfarin: total cost (discounted) | B10: =Results!C4 -> 28415.756 | C10: =IF(val_mode=1,20875.1726832633,28415.7556272264) -> 28415.756 | D10: =B10-C10 -> 0 | E10: =IF(ABS(D10)<0.01,"PASS","CHECK") -> PASS
A11: Apixaban: QALYs (discounted) | B11: =Results!B8 -> 7.4644651 | C11: =IF(val_mode=1,7.46446505520995,7.46446505520995) -> 7.4644651 | D11: =B11-C11 -> 0 | E11: =IF(ABS(D11)<0.000001,"PASS","CHECK") -> PASS
A12: Warfarin: QALYs (discounted) | B12: =Results!C8 -> 7.2281947 | C12: =IF(val_mode=1,7.22819465539138,7.22819465539138) -> 7.2281947 | D12: =B12-C12 -> 0 | E12: =IF(ABS(D12)<0.000001,"PASS","CHECK") -> PASS
A13: Apixaban: life-years (discounted) | B13: =Results!B9 -> 9.3878909 | C13: =IF(val_mode=1,9.38789091607325,9.38789091607325) -> 9.3878909 | D13: =B13-C13 -> 0 | E13: =IF(ABS(D13)<0.000001,"PASS","CHECK") -> PASS
A14: Warfarin: life-years (discounted) | B14: =Results!C9 -> 9.1294309 | C14: =IF(val_mode=1,9.12943090989414,9.12943090989414) -> 9.1294309 | D14: =B14-C14 -> 0 | E14: =IF(ABS(D14)<0.000001,"PASS","CHECK") -> PASS
A15: Apixaban: strokes per 1,000 | B15: =Results!B13 -> 238.60513 | C15: =IF(val_mode=1,238.605132134123,238.605132134123) -> 238.60513 | D15: =B15-C15 -> 0 | E15: =IF(ABS(D15)<0.001,"PASS","CHECK") -> PASS
A16: Warfarin: strokes per 1,000 | B16: =Results!C13 -> 281.7505 | C16: =IF(val_mode=1,281.75050218053,281.75050218053) -> 281.7505 | D16: =B16-C16 -> 0 | E16: =IF(ABS(D16)<0.001,"PASS","CHECK") -> PASS
A17: Incremental cost | B17: =Results!D4 -> -5607.9085 | C17: =IF(val_mode=1,4044.28324657166,-5607.90850603029) -> -5607.9085 | D17: =B17-C17 -> -4.7293724e-11 | E17: =IF(ABS(D17)<0.01,"PASS","CHECK") -> PASS
A18: Incremental QALYs | B18: =Results!D8 -> 0.2362704 | C18: =IF(val_mode=1,0.236270399818563,0.236270399818563) -> 0.2362704 | D18: =B18-C18 -> -1.1546319e-14 | E18: =IF(ABS(D18)<0.000001,"PASS","CHECK") -> PASS
A19: Incremental net monetary benefit | B19: =Results!D18 -> 17421.428 | C19: =IF(val_mode=1,7769.2367443565,17421.4284969585) -> 17421.428 | D19: =B19-C19 -> -5.2750693e-10 | E19: =IF(ABS(D19)<0.05,"PASS","CHECK") -> PASS
A20: Python values are hard-coded from the notebooks (reference case and the 2011-price run). They only match while every other input is at its base value.
A22: C. Reproducing the CADTH worked example (set val_mode = 1) | B22: CADTH (2017) | C22: This model (Python) | D22: Excel (live) | E22: Difference vs CADTH
A23: Warfarin: total cost | B23: 20558 | C23: 20875.173 | D23: =IF(val_mode=1,Results!C4,"set val_mode = 1") -> set val_mode = 1 | E23: =C23/B23-1 -> 0.015428188
A24: Warfarin: QALYs | B24: 7.49 | C24: 7.2281947 | D24: =IF(val_mode=1,Results!C8,"set val_mode = 1") -> set val_mode = 1 | E24: =C24/B24-1 -> -0.034953985
A25: Warfarin: life-years | B25: 9.12 | C25: 9.1294309 | D25: =IF(val_mode=1,Results!C9,"set val_mode = 1") -> set val_mode = 1 | E25: =C25/B25-1 -> 0.001034091
A26: Apixaban: total cost | B26: 24665 | C26: 24919.456 | D26: =IF(val_mode=1,Results!B4,"set val_mode = 1") -> set val_mode = 1 | E26: =C26/B26-1 -> 0.010316478
A27: Apixaban: QALYs | B27: 7.67 | C27: 7.4644651 | D27: =IF(val_mode=1,Results!B8,"set val_mode = 1") -> set val_mode = 1 | E27: =C27/B27-1 -> -0.026797255
A28: Apixaban: life-years | B28: 9.48 | C28: 9.3878909 | D28: =IF(val_mode=1,Results!B9,"set val_mode = 1") -> set val_mode = 1 | E28: =C28/B28-1 -> -0.0097161481
A29: Incremental cost | B29: 4107 | C29: 4044.2832 | D29: =IF(val_mode=1,Results!D4,"set val_mode = 1") -> set val_mode = 1 | E29: =C29/B29-1 -> -0.015270697
A30: Incremental QALYs | B30: 0.18 | C30: 0.2362704 | D30: =IF(val_mode=1,Results!D8,"set val_mode = 1") -> set val_mode = 1 | E30: =C30/B30-1 -> 0.31261333
A31: ICER ($ per QALY) | B31: 22875 | C31: 17117.181 | D31: =IF(val_mode=1,Results!D4/Results!D8,"set val_mode = 1") -> set val_mode = 1 | E31: =C31/B31-1 -> -0.25170793
A33: CADTH values: Guidelines for the Economic Evaluation of Health Technologies: Canada, 4th ed., worked example, CHADS2 = 2 (probabilistic means).
A34: Costs, life-years and incremental cost reproduce within 2%. Incremental QALYs are 31% higher than CADTH's (ICER 25% lower), so this
A35: simplified 5-state model is somewhat favourable to apixaban; the pessimistic treatment-effect scenarios (Scenarios_PSA) address this.
A36: D. Internal checks run in Python (all passed): utilities = 1 gives QALYs = life-years; apixaban ORs = 1 with equal drug cost gives identical
A37: arms; lower stroke OR raises QALYs monotonically; a higher discount rate lowers discounted QALYs.

Sheet Scenarios_PSA
A1: Uncertainty analyses: values from the Python notebooks (not live formulas)
A2: Re-run the notebooks (05 PSA, 06 sensitivity) to regenerate. Single scenarios can also be reproduced live by changing Inputs.
A4: Scenario | B4: Incremental cost | C4: Incremental QALYs | D4: Result | E4: INMB at $50,000/QALY
A5: Reference case (generic apixaban, 2026 ODB price) | B5: -5607.9085 | C5: 0.2362704 | D5: Dominant | E5: 17421.428
A6: Brand apixaban price (Eliquis, ODB list) | B6: 1280.2518 | C6: 0.2362704 | D6: $5,419/QALY | E6: 10533.268
A7: Discount rate 0% | B7: -6194.058 | C7: 0.28055307 | D7: Dominant | E7: 20221.712
A8: Discount rate 3% | B8: -5104.6185 | C8: 0.20064613 | D8: Dominant | E8: 15136.925
A9: Time horizon 2 years (trial follow-up) | B9: -821.94134 | C9: 0.0041946947 | D9: Dominant | E9: 1031.6761
A10: Time horizon 10 years | B10: -4357.3973 | C10: 0.097462127 | D10: Dominant | E10: 9230.5037
A11: Apixaban effect wanes 5%/yr after year 2 | B11: -4912.0923 | C11: 0.20689702 | D11: Dominant | E11: 15256.943
A12: All apixaban ORs at upper 95% CI | B12: -2613.6415 | C12: 0.092487617 | D12: Dominant | E12: 7238.0224
A13: No INR monitoring cost for warfarin | B13: -3282.9416 | C13: 0.2362704 | D13: Dominant | E13: 15096.462
A14: Cohort starts at age 80 | B14: -3125.2016 | C14: 0.10517219 | D14: Dominant | E14: 8383.8112
A17: One-way sensitivity (all parameters, sorted by swing) | B17: Low value | C17: High value | D17: INMB at low | E17: INMB at high | F17: Swing
A18: Apixaban OR: stroke | B18: 0.65 | C18: 0.95 | D18: 23049.414 | E18: 11203.656 | F18: 11845.758
A19: Apixaban 5 mg BID, annual drug cost | B19: 149.1681 | C19: 1193.3448 | D19: 18569.455 | E19: 10533.268 | F19: 8036.187
A20: Non-vascular death at age 70 (annual) | B20: 0.025 | C20: 0.041 | D20: 21029.62 | E20: 14837.83 | F20: 6191.7903
A21: Apixaban OR: ICH | B21: 0.3 | C21: 0.58 | D21: 18892.66 | E21: 15481.935 | F21: 3410.7251
A22: Apixaban OR: major bleed | B22: 0.68 | C22: 0.94 | D22: 18973.708 | E22: 15686.396 | F22: 3287.312
A23: Stroke rate on warfarin (annual) | B23: 0.012 | C23: 0.02 | D23: 15844.583 | E23: 18840.105 | F23: 2995.5222
A24: ICH rate on warfarin (annual) | B24: 0.006 | C24: 0.01 | D24: 15980.089 | E24: 18824.553 | F24: 2844.4643
A25: Utility: AF, no prior event | B25: 0.75 | C25: 0.87 | D25: 16041.3 | E25: 18801.557 | F25: 2760.2575
A26: Aspirin RR: stroke | B26: 0.99 | C26: 2.65 | D26: 16405.626 | E26: 18873.403 | F26: 2467.7774
A27: INR monitoring, annual (warfarin only) | B27: 164.80942 | C27: 494.42825 | D27: 16258.945 | E27: 18583.912 | F27: 2324.9669
A28: Utility: after minor stroke / ICH | B28: 0.67 | C28: 0.83 | D28: 18085.052 | E28: 16757.805 | F28: 1327.2476
A29: Stroke risk after prior stroke/ICH | B29: 1.2 | C29: 3.5 | D29: 16877.675 | E29: 18033.986 | F29: 1156.3109
... A67: Disutility: TIA | B67: 0.087 | C67: 0.119 | D67: 17421.505 | E67: 17421.352 | F67: 0.15238458
A69: Probabilistic analysis (5,000 draws, seed 2026) | B69: Value
A70: Apixaban: expected cost | B70: 23168.051
A71: Apixaban: expected QALYs | B71: 7.4483362
A72: Warfarin: expected cost | B72: 28757.329
A73: Warfarin: expected QALYs | B73: 7.2125074
A74: Incremental cost (mean) | B74: -5589.2772
A75: Incremental cost, 2.5th percentile | B75: -8352.1472
A76: Incremental cost, 97.5th percentile | B76: -3242.3247
A77: Incremental QALYs (mean) | B77: 0.23582872
A78: Incremental QALYs, 2.5th percentile | B78: 0.12658787
A79: Incremental QALYs, 97.5th percentile | B79: 0.35878141
A80: Share of draws where apixaban is dominant | B80: 1
A81: Probability cost-effective at $50,000/QALY | B81: 1

Sheet CMA
A1: Cost comparison of oral anticoagulants at current Ontario Drug Benefit prices
A3: Regimen | B3: Dose / frequency | C3: Unit price (ODB) | D3: Units per day | E3: Daily cost | F3: Annual cost | G3: Source
A4: Apixaban 5 mg (generic) | B4: 1 tablet twice daily | C4: =apx_price_tab -> 0.4084 | D4: 2 | E4: =C4*D4 -> 0.8168 | F4: =E4*days_yr -> 298.3362 | G4: ODB formulary, Oct 2026
A5: Edoxaban 60 mg (generic) | B5: 1 tablet once daily | C5: 0.7348 | D5: 1 | E5: =C5*D5 -> 0.7348 | F5: =E5*days_yr -> 268.3857 | G5: ODB Formulary, generic edoxaban 60 mg, Oct 2026
A6: Apixaban 5 mg (Eliquis, brand) | B6: 1 tablet twice daily | C6: 1.6336 | D6: 2 | E6: =C6*D6 -> 3.2672 | F6: =E6*days_yr -> 1193.3448 | G6: ODB Formulary, Oct 2026
A7: Warfarin 5 mg + INR monitoring | B7: Daily, plus INR tests | E7: =F7/days_yr -> 1.0519612 | F7: =c_warfarin+c_inr -> 384.22883 | G7: CADTH worked example (warfarin 2011 ODB; INR inflated to 2025 CAD)
A9: Reading this table: a cost-minimization comparison is only valid between options judged to have similar clinical effects. Among DOACs that judgement belongs to the clinical review; versus warfarin, apixaban is NOT clinically equivalent (fewer strokes and ICH), which is why the main analysis is a cost-utility analysis.
A12: Rivaroxaban and dabigatran are omitted: their current ODB prices could not be verified when this model was built.

Sheet BIA
A1: Budget impact — switching residual warfarin users to generic apixaban, Ontario public drug programs, years 1-3
A3: Input | B3: Value | C3: Source / note
A4: Ontario population aged 65+ | B4: 3100000 | C4: Ontario Ministry of Finance population projections, 2025 (approx. 3.1 million)
A5: AF prevalence, age 65+ | B5: 0.059 | C5: Feinberg et al., Arch Intern Med 1995. ASSUMPTION that it applies to Ontario today
A6: Share of AF patients on an oral anticoagulant | B6: 0.6 | C6: ASSUMPTION
A7: Share of anticoagulated patients still on warfarin | B7: 0.15 | C7: ASSUMPTION. No current Ontario estimate found; most uncertain BIA input (try 5% and 30%)
A8: Uptake: share of warfarin users switched, year 1 | B8: 0.25 | C8: ASSUMPTION
A9: Uptake, year 2 | B9: 0.5 | C9: ASSUMPTION
A10: Uptake, year 3 | B10: 0.75 | C10: ASSUMPTION
A12: Eligible warfarin users (Ontario, 65+) | B12: =pop_65*af_prev*share_oac*share_warf -> 16461
A13: Drug-plan cost difference per patient-year (apixaban − warfarin drug only) | B13: =c_apixaban-c_warfarin -> 243.7262 | C13: CDA-AMC BIA reference case: drug-plan perspective, drug acquisition cost only (no mark-up / dispensing fee)
A15: Year | B15: Patients switched | C15: Drug-plan impact | D15: Health-system impact (drugs, INR, events, long-term care)
A16: Year 1 | B16: =$B$12*uptake_y1 -> 4115.25 | C16: =B16*$B$13 -> 1002994.2 | D16: =B16*hs_diff_y1 -> -1599025.6
A17: Year 2 | B17: =$B$12*uptake_y2 -> 8230.5 | C17: =B17*$B$13 -> 2005988.5 | D17: =B17*hs_diff_y2 -> -3659910.3
A18: Year 3 | B18: =$B$12*uptake_y3 -> 12345.75 | C18: =B18*$B$13 -> 3008982.7 | D18: =B18*hs_diff_y3 -> -5993195.6
A19: 3-year total | C19: =SUM(C16:C18) -> 6017965.5 | D19: =SUM(D16:D18) -> -11252132
A21: Health-system impact uses the per-patient cost difference in model years 1, 2 and 3 (Results sheet), i.e. it treats each year's switchers as starting therapy at age 70 — a simplification of a prevalent population.

Sheet LifeTable
A1: Age | B1: qx (StatCan 2021-2023) | C1: ln(qx) | E1: Gompertz fit
A2: 70 | B2: 0.01819 | C2: =LN(B2) -> -4.0068833 | E2: Slope (per year of age) | F2: =SLOPE(C2:C6,A2:A6) -> 0.10463355
A3: 75 | B3: 0.0295 | C3: =LN(B3) -> -3.523365 | E3: Intercept | F3: =INTERCEPT(C2:C6,A2:A6) -> -11.357682
A4: 80 | B4: 0.04912 | C4: =LN(B4) -> -3.013489 | E4: qx at reference age 70 (fitted) | F4: =EXP(F3+F2*ref_age) -> 0.017715167
A5: 85 | B5: 0.08399 | C5: =LN(B5) -> -2.4770575
A6: 90 | B6: 0.14746 | C6: =LN(B6) -> -1.9141983 | E6: Source: Statistics Canada, Life tables, Canada, 2021-2023, complete life table (both sexes), Table 13-10-0114.
E7: Fitted qx at each age = EXP(intercept + slope x age); used only for its age GRADIENT relative to age 70.
A9: Age | B9: Fitted qx | C9: Model background death (annual)
A10: 70 | B10: =MIN(EXP(gomp_int+gomp_slope*A10),1) -> 0.017715167 | C10: =MIN(p_nonvasc_death*B10/qx_ref,0.999) -> 0.033
A11: 71 | B11: =MIN(EXP(gomp_int+gomp_slope*A11),1) -> 0.019669215 | C11: =MIN(p_nonvasc_death*B11/qx_ref,0.999) -> 0.036640021
A12: 72 | B12: =MIN(EXP(gomp_int+gomp_slope*A12),1) -> 0.021838801 | C12: =MIN(p_nonvasc_death*B12/qx_ref,0.999) -> 0.040681549
A13: 73 | B13: =MIN(EXP(gomp_int+gomp_slope*A13),1) -> 0.024247701 | C13: =MIN(p_nonvasc_death*B13/qx_ref,0.999) -> 0.045168873
A14: 74 | B14: =MIN(EXP(gomp_int+gomp_slope*A14),1) -> 0.026922311 | C14: =MIN(p_nonvasc_death*B14/qx_ref,0.999) -> 0.050151165
A15: 75 | B15: =MIN(EXP(gomp_int+gomp_slope*A15),1) -> 0.029891941 | C15: =MIN(p_nonvasc_death*B15/qx_ref,0.999) -> 0.055683023
A16: 76 | B16: =MIN(EXP(gomp_int+gomp_slope*A16),1) -> 0.033189131 | C16: =MIN(p_nonvasc_death*B16/qx_ref,0.999) -> 0.061825064
A17: 77 | B17: =MIN(EXP(gomp_int+gomp_slope*A17),1) -> 0.036850014 | C17: =MIN(p_nonvasc_death*B17/qx_ref,0.999) -> 0.068644595
A18: 78 | B18: =MIN(EXP(gomp_int+gomp_slope*A18),1) -> 0.040914706 | C18: =MIN(p_nonvasc_death*B18/qx_ref,0.999) -> 0.076216345
A19: 79 | B19: =MIN(EXP(gomp_int+gomp_slope*A19),1) -> 0.045427748 | C19: =MIN(p_nonvasc_death*B19/qx_ref,0.999) -> 0.084623287
A20: 80 | B20: =MIN(EXP(gomp_int+gomp_slope*A20),1) -> 0.050438595 | C20: =MIN(p_nonvasc_death*B20/qx_ref,0.999) -> 0.093957546
A21: 81 | B21: =MIN(EXP(gomp_int+gomp_slope*A21),1) -> 0.056002156 | C21: =MIN(p_nonvasc_death*B21/qx_ref,0.999) -> 0.10432141
... A40: 100 | B40: =MIN(EXP(gomp_int+gomp_slope*A40),1) -> 0.40888241 | C40: =MIN(p_nonvasc_death*B40/qx_ref,0.999) -> 0.76167047

Sheet Apixaban
A1: Apixaban arm — cohort Markov trace (120 x 3-month cycles)
A2: Arm flag (1 = apixaban, 0 = warfarin) | B2: 1 | D2: Annual cost of the anticoagulant strategy (state 0) | H2: =IF($B$2=1,c_apixaban,c_warfarin+c_inr) -> 298.3362
A3: Columns grouped by state (S0 = AF on anticoagulant, S1 = post minor stroke/ICH, S2 = post major stroke, S3 = post major bleed, S4 = dead). Occupancy columns are start-of-cycle; 'New' columns feed the next row.
A5: Cycle | B5: Age | C5: Discount factor | D5: Apixaban effect multiplier (waning) | E5: Background death (annual) | F5: Stroke age factor | G5: Occupancy S0 | H5: Occupancy S1 | I5: Occupancy S2 | J5: Occupancy S3 | K5: Occupancy S4 | L5: S0: p background death | M5: S0: survivors of background death | N5: S0: p stroke | O5: S0: p ich | P5: S0: p mb | Q5: S0: p mi | R5: S0: p tia | S5: S0: p minor | T5: S0: n stroke | U5: S0: n ich | V5: S0: n mb | W5: S0: n mi | X5: S0: n tia | Y5: S0: n minor | Z5: S0: fatal strokes | AA5: S0: non-fatal major strokes | AB5: S0: non-fatal minor strokes | AC5: S0: non-fatal ICH | AD5: S0: non-fatal major bleeds | AE5: S0: fatal MI | AF5: S0: non-fatal MI | AG5: S0: remain (no state-changing event) | AH5: S0: event costs | AI5: S0: event QALY loss | AJ5: S0: all deaths this cycle | AK5: S1: p background death | AL5: S1: survivors of background death | AM5: S1: p stroke | AN5: S1: p ich | AO5: S1: p mb | AP5: S1: p mi | AQ5: S1: p tia | AR5: S1: p minor | AS5: S1: n stroke | AT5: S1: n ich | AU5: S1: n mb | AV5: S1: n mi | AW5: S1: n tia | AX5: S1: n minor | AY5: S1: fatal strokes | AZ5: S1: non-fatal major strokes | BA5: S1: non-fatal minor strokes | BB5: S1: non-fatal ICH | BC5: S1: non-fatal major bleeds | BD5: S1: fatal MI | BE5: S1: non-fatal MI | BF5: S1: remain (no state-changing event) | BG5: S1: event costs | BH5: S1: event QALY loss | BI5: S1: all deaths this cycle | BJ5: S2: p background death | BK5: S2: survivors of background death | BL5: S2: p stroke | BM5: S2: p ich | BN5: S2: p mb | BO5: S2: p mi | BP5: S2: p tia | BQ5: S2: p minor | BR5: S2: n stroke | BS5: S2: n ich | BT5: S2: n mb | BU5: S2: n mi | BV5: S2: n tia | BW5: S2: n minor | BX5: S2: fatal strokes | BY5: S2: non-fatal major strokes | BZ5: S2: non-fatal minor strokes | CA5: S2: non-fatal ICH | CB5: S2: non-fatal major bleeds | CC5: S2: fatal MI | CD5: S2: non-fatal MI | CE5: S2: remain (no state-changing event) | CF5: S2: event costs | CG5: S2: event QALY loss | CH5: S2: all deaths this cycle | CI5: S3: p background death | CJ5: S3: survivors of background death | CK5: S3: p stroke | CL5: S3: p ich | CM5: S3: p mb | CN5: S3: p mi | CO5: S3: p tia | CP5: S3: p minor | CQ5: S3: n stroke | CR5: S3: n ich | CS5: S3: n mb | CT5: S3: n mi | CU5: S3: n tia | CV5: S3: n minor | CW5: S3: fatal strokes | CX5: S3: non-fatal major strokes | CY5: S3: non-fatal minor strokes | CZ5: S3: non-fatal ICH | DA5: S3: non-fatal major bleeds | DB5: S3: fatal MI | DC5: S3: non-fatal MI | DD5: S3: remain (no state-changing event) | DE5: S3: event costs | DF5: S3: event QALY loss | DG5: S3: all deaths this cycle | DH5: New S0 (next cycle) | DI5: New S1 (next cycle) | DJ5: New S2 (next cycle) | DK5: New S3 (next cycle) | DL5: New S4 (next cycle) | DM5: Mass check (=1) | DN5: Drug cost | DO5: Long-term care cost | DP5: Event cost | DQ5: Total cost (undiscounted) | DR5: QALYs (undiscounted) | DS5: Life-years (undiscounted) | DT5: Total cost (discounted) | DU5: Drug cost (disc.) | DV5: Event cost (disc.) | DW5: Long-term cost (disc.) | DX5: QALYs (discounted) | DY5: Life-years (discounted) | DZ5: Strokes this cycle | EA5: ICH this cycle | EB5: Major bleeds this cycle | EC5: Discounted years on anticoagulant (S0)
A6: 0 | B6: =start_age+A6*dt -> 70 | C6: =(1+disc_rate)^-(A6*dt) -> 1 | D6: =IF(A6*dt>=wane_start,(1-wane_decay)^(A6*dt-wane_start),1) -> 1 | E6: =MIN(p_nonvasc_death*MIN(EXP(gomp_int+gomp_slope*INT(B6)),1)/qx_ref,0.999) -> 0.033 | F6: =rr_stroke_per_decade^((B6-ref_age)/10) -> 1 | G6: 1 | H6: 0 | I6: 0 | J6: 0 | K6: 0 | L6: =1-EXP(LN(1-E6)*dt) -> 0.0083541048 | M6: =G6*(1-L6) -> 0.9916459 | N6: =IF(Apixaban!$B$2=1,EXP(LN(or_apx_stroke)*D6)*(1-EXP(-r_stroke*F6*dt))/(1-(1-EXP(-r_stroke*F6*dt))+EXP(LN(or_apx_stroke)*D6)*(1-EXP(-r_stroke*F6*dt))),(1-EXP(-r_stroke*F6*dt))) -> 0.0031818279 | O6: =IF(Apixaban!$B$2=1,EXP(LN(or_apx_ich)*D6)*(1-EXP(-r_ich*dt))/(1-(1-EXP(-r_ich*dt))+EXP(LN(or_apx_ich)*D6)*(1-EXP(-r_ich*dt))),(1-EXP(-r_ich*dt))) -> 0.00084351325 | P6: =IF(Apixaban!$B$2=1,EXP(LN(or_apx_mb)*D6)*(1-EXP(-r_mb*dt))/(1-(1-EXP(-r_mb*dt))+EXP(LN(or_apx_mb)*D6)*(1-EXP(-r_mb*dt))),(1-EXP(-r_mb*dt))) -> 0.0066944691 | Q6: =IF(Apixaban!$B$2=1,EXP(LN(or_apx_mi)*D6)*(1-EXP(-r_mi*dt))/(1-(1-EXP(-r_mi*dt))+EXP(LN(or_apx_mi)*D6)*(1-EXP(-r_mi*dt))),(1-EXP(-r_mi*dt))) -> 0.0013232192 | R6: =(1-EXP(-r_tia*dt)) -> 0.0020060282 | S6: =(1-EXP(-r_minor*dt)) -> 0.043793769 | T6: =M6*N6 -> 0.0031552465 | U6: =M6*O6 -> 0.00083646645 | V6: =M6*P6 -> 0.0066385428 | W6: =M6*Q6 -> 0.0013121648 | X6: =M6*R6 -> 0.0019892696 | Y6: =M6*S6 -> 0.043427911 | Z6: =T6*f_stroke_fatal -> 0.00074779343 | AA6: =T6*(1-f_stroke_fatal)*f_stroke_major -> 0.00080168188 | AB6: =T6*(1-f_stroke_fatal)*(1-f_stroke_major) -> 0.0016057712 | AC6: =U6*(1-f_bleed_fatal) -> 0.00076620327 | AD6: =V6*(1-f_bleed_fatal) -> 0.0060809052 | AE6: =W6*f_mi_fatal -> 0.00015877195 | AF6: =W6-AE6 -> 0.0011533929 | AG6: =M6-T6-U6-V6-AE6 -> 0.98085687 | AH6: =Z6*c_stroke_fatal+AA6*c_stroke_major+AB6*c_stroke_minor+U6*c_ich+V6*c_major_bleed+AE6*c_mi_fatal+AF6*c_mi_nonfatal+X6*c_tia+Y6*c_minor_bleed -> 212.93878 | AI6: =dt*(AF6*dec_mi+AD6*dec_major_bleed+Y6*dec_minor_bleed+X6*dec_tia) -> 0.00036826875 | AJ6: =G6*L6+Z6+U6-AC6+V6-AD6+AE6 -> 0.0098885709 | AK6: =1-EXP(LN(1-E6)*hr_death_prior_stroke*dt) -> 0.019110191 | AL6: =H6*(1-AK6) -> 0 | AM6: =(1-EXP(-r_stroke*F6*rr_stroke_prior*rr_asa_stroke*dt)) -> 0.014268505 | AN6: =(1-EXP(-r_ich*rr_asa_ich*dt)) -> 0.0010235777 | AO6: =(1-EXP(-r_mb*rr_asa_mb*dt)) -> 0.0095180967 | AP6: =(1-EXP(-r_mi*rr_asa_mi*dt)) -> 0.0021341352 | AQ6: =(1-EXP(-r_tia*rr_asa_tia*dt)) -> 0.0031276457 | AR6: =(1-EXP(-r_minor*rr_asa_minor*dt)) -> 0.027818195 | AS6: =AL6*AM6 -> 0 | AT6: =AL6*AN6 -> 0 | AU6: =AL6*AO6 -> 0 | AV6: =AL6*AP6 -> 0 | AW6: =AL6*AQ6 -> 0 | AX6: =AL6*AR6 -> 0 | AY6: =AS6*f_stroke_fatal_recur -> 0 | AZ6: =AS6*(1-f_stroke_fatal_recur)*f_stroke_major -> 0 | BA6: =AS6*(1-f_stroke_fatal_recur)*(1-f_stroke_major) -> 0 | BB6: =AT6*(1-f_bleed_fatal) -> 0 | BC6: =AU6*(1-f_bleed_fatal) -> 0 | BD6: =AV6*f_mi_fatal -> 0 | BE6: =AV6-BD6 -> 0 | BF6: =AL6-AS6-AT6-AU6-BD6 -> 0 | BG6: =AY6*c_stroke_fatal+AZ6*c_stroke_major+BA6*c_stroke_minor+AT6*c_ich+AU6*c_major_bleed+BD6*c_mi_fatal+BE6*c_mi_nonfatal+AW6*c_tia+AX6*c_minor_bleed -> 0 | BH6: =dt*(BE6*dec_mi+BC6*dec_major_bleed+AX6*dec_minor_bleed+AW6*dec_tia) -> 0 | BI6: =H6*AK6+AY6+AT6-BB6+AU6-BC6+BD6 -> 0 | BJ6: =1-EXP(LN(1-E6)*hr_death_prior_stroke*dt) -> 0.019110191 | BK6: =I6*(1-BJ6) -> 0 | BL6: =(1-EXP(-r_stroke*F6*rr_stroke_prior*rr_asa_stroke*dt)) -> 0.014268505 | BM6: =(1-EXP(-r_ich*rr_asa_ich*dt)) -> 0.0010235777 | BN6: =(1-EXP(-r_mb*rr_asa_mb*dt)) -> 0.0095180967 | BO6: =(1-EXP(-r_mi*rr_asa_mi*dt)) -> 0.0021341352 | BP6: =(1-EXP(-r_tia*rr_asa_tia*dt)) -> 0.0031276457 | BQ6: =(1-EXP(-r_minor*rr_asa_minor*dt)) -> 0.027818195 | BR6: =BK6*BL6 -> 0 | BS6: =BK6*BM6 -> 0 | BT6: =BK6*BN6 -> 0 | BU6: =BK6*BO6 -> 0 | BV6: =BK6*BP6 -> 0 | BW6: =BK6*BQ6 -> 0 | BX6: =BR6*f_stroke_fatal_recur -> 0 | BY6: =BR6*(1-f_stroke_fatal_recur)*f_stroke_major -> 0 | BZ6: =BR6*(1-f_stroke_fatal_recur)*(1-f_stroke_major) -> 0 | CA6: =BS6*(1-f_bleed_fatal) -> 0 | CB6: =BT6*(1-f_bleed_fatal) -> 0 | CC6: =BU6*f_mi_fatal -> 0 | CD6: =BU6-CC6 -> 0 | CE6: =BK6-BR6-BS6-BT6-CC6 -> 0 | CF6: =BX6*c_stroke_fatal+BY6*c_stroke_major+BZ6*c_stroke_minor+BS6*c_ich+BT6*c_major_bleed+CC6*c_mi_fatal+CD6*c_mi_nonfatal+BV6*c_tia+BW6*c_minor_bleed -> 0 | CG6: =dt*(CD6*dec_mi+CB6*dec_major_bleed+BW6*dec_minor_bleed+BV6*dec_tia) -> 0 | CH6: =I6*BJ6+BX6+BS6-CA6+BT6-CB6+CC6 -> 0 | CI6: =1-EXP(LN(1-E6)*dt) -> 0.0083541048 | CJ6: =J6*(1-CI6) -> 0 | CK6: =(1-EXP(-r_stroke*F6*rr_asa_stroke*dt)) -> 0.0065111099 | CL6: =(1-EXP(-r_ich*rr_asa_ich*dt)) -> 0.0010235777 | CM6: =(1-EXP(-r_mb*rr_asa_mb*dt)) -> 0.0095180967 | CN6: =(1-EXP(-r_mi*rr_asa_mi*dt)) -> 0.0021341352 | CO6: =(1-EXP(-r_tia*rr_asa_tia*dt)) -> 0.0031276457 | CP6: =(1-EXP(-r_minor*rr_asa_minor*dt)) -> 0.027818195 | CQ6: =CJ6*CK6 -> 0 | CR6: =CJ6*CL6 -> 0 | CS6: =CJ6*CM6 -> 0 | CT6: =CJ6*CN6 -> 0 | CU6: =CJ6*CO6 -> 0 | CV6: =CJ6*CP6 -> 0 | CW6: =CQ6*f_stroke_fatal -> 0 | CX6: =CQ6*(1-f_stroke_fatal)*f_stroke_major -> 0 | CY6: =CQ6*(1-f_stroke_fatal)*(1-f_stroke_major) -> 0 | CZ6: =CR6*(1-f_bleed_fatal) -> 0 | DA6: =CS6*(1-f_bleed_fatal) -> 0 | DB6: =CT6*f_mi_fatal -> 0 | DC6: =CT6-DB6 -> 0 | DD6: =CJ6-CQ6-CR6-CS6-DB6 -> 0 | DE6: =CW6*c_stroke_fatal+CX6*c_stroke_major+CY6*c_stroke_minor+CR6*c_ich+CS6*c_major_bleed+DB6*c_mi_fatal+DC6*c_mi_nonfatal+CU6*c_tia+CV6*c_minor_bleed -> 0 | DF6: =dt*(DC6*dec_mi+DA6*dec_major_bleed+CV6*dec_minor_bleed+CU6*dec_tia) -> 0 | DG6: =J6*CI6+CW6+CR6-CZ6+CS6-DA6+DB6 -> 0 | DH6: =AG6 -> 0.98085687 | DI6: =AB6+AC6+BF6+BA6+BB6+BC6+CY6+CZ6 -> 0.0023719745 | DJ6: =AA6+AZ6+BY6+CX6+CE6+BZ6+CA6+CB6 -> 0.00080168188 | DK6: =AD6+DD6+DA6 -> 0.0060809052 | DL6: =K6+AJ6+BI6+CH6+DG6 -> 0.0098885709 | DM6: =SUM(DH6:DL6) -> 1 | DN6: =dt*(G6*Apixaban!$H$2+(H6+I6+J6)*c_aspirin) -> 74.58405 | DO6: =dt*(H6*c_lt_minor_stroke+I6*c_lt_major_stroke) -> 0 | DP6: =AH6+BG6+CF6+DE6 -> 212.93878 | DQ6: =DN6+DO6+DP6 -> 287.52283 | DR6: =dt*(G6*(u_af-dec_per_year_over_70*MAX(B6-ref_age,0))+H6*(u_minor_stroke-dec_per_year_over_70*MAX(B6-ref_age,0))+I6*(u_major_stroke-dec_per_year_over_70*MAX(B6-ref_age,0))+J6*(u_af-dec_per_year_over_70*MAX(B6-ref_age,0)))-AI6-BH6-CG6-DF6 -> 0.20213173 | DS6: =dt*(G6+H6+I6+J6) -> 0.25 | DT6: =DQ6*C6 -> 287.52283 | DU6: =DN6*C6 -> 74.58405 | DV6: =DP6*C6 -> 212.93878 | DW6: =DO6*C6 -> 0 | DX6: =DR6*C6 -> 0.20213173 | DY6: =DS6*C6 -> 0.25 | DZ6: =T6+AS6+BR6+CQ6 -> 0.0031552465 | EA6: =U6+AT6+BS6+CR6 -> 0.00083646645 | EB6: =V6+AU6+BT6+CS6 -> 0.0066385428 | EC6: =G6*dt*C6 -> 0.25
A7: 1 | B7: =start_age+A7*dt -> 70.25 | C7: =(1+disc_rate)^-(A7*dt) -> 0.99628477 | D7: =IF(A7*dt>=wane_start,(1-wane_decay)^(A7*dt-wane_start),1) -> 1 | E7: =MIN(p_nonvasc_death*MIN(EXP(gomp_int+gomp_slope*INT(B7)),1)/qx_ref,0.999) -> 0.033 | F7: =rr_stroke_per_decade^((B7-ref_age)/10) -> 1.0101882 | G7: =DH6 -> 0.98085687 | H7: =DI6 -> 0.0023719745 | I7: =DJ6 -> 0.00080168188 | J7: =DK6 -> 0.0060809052 | K7: =DL6 -> 0.0098885709 | L7: =1-EXP(LN(1-E7)*dt) -> 0.0083541048 | M7: =G7*(1-L7) -> 0.97266269 | N7: =IF(Apixaban!$B$2=1,EXP(LN(or_apx_stroke)*D7)*(1-EXP(-r_stroke*F7*dt))/(1-(1-EXP(-r_stroke*F7*dt))+EXP(LN(or_apx_stroke)*D7)*(1-EXP(-r_stroke*F7*dt))),(1-EXP(-r_stroke*F7*dt))) -> 0.0032142065 | O7: =IF(Apixaban!$B$2=1,EXP(LN(or_apx_ich)*D7)*(1-EXP(-r_ich*dt))/(1-(1-EXP(-r_ich*dt))+EXP(LN(or_apx_ich)*D7)*(1-EXP(-r_ich*dt))),(1-EXP(-r_ich*dt))) -> 0.00084351325 | P7: =IF(Apixaban!$B$2=1,EXP(LN(or_apx_mb)*D7)*(1-EXP(-r_mb*dt))/(1-(1-EXP(-r_mb*dt))+EXP(LN(or_apx_mb)*D7)*(1-EXP(-r_mb*dt))),(1-EXP(-r_mb*dt))) -> 0.0066944691 | Q7: =IF(Apixaban!$B$2=1,EXP(LN(or_apx_mi)*D7)*(1-EXP(-r_mi*dt))/(1-(1-EXP(-r_mi*dt))+EXP(LN(or_apx_mi)*D7)*(1-EXP(-r_mi*dt))),(1-EXP(-r_mi*dt))) -> 0.0013232192 | R7: =(1-EXP(-r_tia*dt)) -> 0.0020060282 | S7: =(1-EXP(-r_minor*dt)) -> 0.043793769 | T7: =M7*N7 -> 0.0031263388 | U7: =M7*O7 -> 0.00082045386 | V7: =M7*P7 -> 0.0065114603 | W7: =M7*Q7 -> 0.0012870459 | X7: =M7*R7 -> 0.0019511887 | Y7: =M7*S7 -> 0.042596565 | Z7: =T7*f_stroke_fatal -> 0.00074094229 | AA7: =T7*(1-f_stroke_fatal)*f_stroke_major -> 0.00079433703 | AB7: =T7*(1-f_stroke_fatal)*(1-f_stroke_major) -> 0.0015910595 | AC7: =U7*(1-f_bleed_fatal) -> 0.00075153574 | AD7: =V7*(1-f_bleed_fatal) -> 0.0059644976 | AE7: =W7*f_mi_fatal -> 0.00015573255 | AF7: =W7-AE7 -> 0.0011313133 | AG7: =M7-T7-U7-V7-AE7 -> 0.9620487 | AH7: =Z7*c_stroke_fatal+AA7*c_stroke_major+AB7*c_stroke_minor+U7*c_ich+V7*c_major_bleed+AE7*c_mi_fatal+AF7*c_mi_nonfatal+X7*c_tia+Y7*c_minor_bleed -> 210.02608 | AI7: =dt*(AF7*dec_mi+AD7*dec_major_bleed+Y7*dec_minor_bleed+X7*dec_tia) -> 0.00036121893 | AJ7: =G7*L7+Z7+U7-AC7+V7-AD7+AE7 -> 0.0097067367 | AK7: =1-EXP(LN(1-E7)*hr_death_prior_stroke*dt) -> 0.019110191 | AL7: =H7*(1-AK7) -> 0.0023266456 | AM7: =(1-EXP(-r_stroke*F7*rr_stroke_prior*rr_asa_stroke*dt)) -> 0.014412823 | AN7: =(1-EXP(-r_ich*rr_asa_ich*dt)) -> 0.0010235777 | AO7: =(1-EXP(-r_mb*rr_asa_mb*dt)) -> 0.0095180967 | AP7: =(1-EXP(-r_mi*rr_asa_mi*dt)) -> 0.0021341352 | AQ7: =(1-EXP(-r_tia*rr_asa_tia*dt)) -> 0.0031276457 | AR7: =(1-EXP(-r_minor*rr_asa_minor*dt)) -> 0.027818195 | AS7: =AL7*AM7 -> 3.3533531e-05 | AT7: =AL7*AN7 -> 2.3815025e-06 | AU7: =AL7*AO7 -> 2.2145238e-05 | AV7: =AL7*AP7 -> 4.9653762e-06 | AW7: =AL7*AQ7 -> 7.276923e-06 | AX7: =AL7*AR7 -> 6.4723081e-05 | AY7: =AS7*f_stroke_fatal_recur -> 1.2477491e-05 | AZ7: =AS7*(1-f_stroke_fatal_recur)*f_stroke_major -> 7.0116611e-06 | BA7: =AS7*(1-f_stroke_fatal_recur)*(1-f_stroke_major) -> 1.4044378e-05 | BB7: =AT7*(1-f_bleed_fatal) -> 2.1814563e-06 | BC7: =AU7*(1-f_bleed_fatal) -> 2.0285038e-05 | BD7: =AV7*f_mi_fatal -> 6.0081052e-07 | BE7: =AV7-BD7 -> 4.3645657e-06 | BF7: =AL7-AS7-AT7-AU7-BD7 -> 0.0022679845 | BG7: =AY7*c_stroke_fatal+AZ7*c_stroke_major+BA7*c_stroke_minor+AT7*c_ich+AU7*c_major_bleed+BD7*c_mi_fatal+BE7*c_mi_nonfatal+AW7*c_tia+AX7*c_minor_bleed -> 1.46952 | BH7: =dt*(BE7*dec_mi+BC7*dec_major_bleed+AX7*dec_minor_bleed+AW7*dec_tia) -> 1.0006793e-06 | BI7: =H7*AK7+AY7+AT7-BB7+AU7-BC7+BD7 -> 6.0467433e-05 | BJ7: =1-EXP(LN(1-E7)*hr_death_prior_stroke*dt) -> 0.019110191 | BK7: =I7*(1-BJ7) -> 0.00078636159 | BL7: =(1-EXP(-r_stroke*F7*rr_stroke_prior*rr_asa_stroke*dt)) -> 0.014412823 | BM7: =(1-EXP(-r_ich*rr_asa_ich*dt)) -> 0.0010235777 | BN7: =(1-EXP(-r_mb*rr_asa_mb*dt)) -> 0.0095180967 | BO7: =(1-EXP(-r_mi*rr_asa_mi*dt)) -> 0.0021341352 | BP7: =(1-EXP(-r_tia*rr_asa_tia*dt)) -> 0.0031276457 | BQ7: =(1-EXP(-r_minor*rr_asa_minor*dt)) -> 0.027818195 | BR7: =BK7*BL7 -> 1.133369e-05 | BS7: =BK7*BM7 -> 8.0490217e-07 | BT7: =BK7*BN7 -> 7.4846657e-06 | BU7: =BK7*BO7 -> 1.6782019e-06 | BV7: =BK7*BP7 -> 2.4594604e-06 | BW7: =BK7*BQ7 -> 2.187516e-05 | BX7: =BR7*f_stroke_fatal_recur -> 4.2171528e-06 | BY7: =BR7*(1-f_stroke_fatal_recur)*f_stroke_major -> 2.369807e-06 | BZ7: =BR7*(1-f_stroke_fatal_recur)*(1-f_stroke_major) -> 4.7467305e-06 | CA7: =BS7*(1-f_bleed_fatal) -> 7.3729039e-07 | CB7: =BT7*(1-f_bleed_fatal) -> 6.8559538e-06 | CC7: =BU7*f_mi_fatal -> 2.0306243e-07 | CD7: =BU7-CC7 -> 1.4751395e-06 | CE7: =BK7-BR7-BS7-BT7-CC7 -> 0.00076653527 | CF7: =BX7*c_stroke_fatal+BY7*c_stroke_major+BZ7*c_stroke_minor+BS7*c_ich+BT7*c_major_bleed+CC7*c_mi_fatal+CD7*c_mi_nonfatal+BV7*c_tia+BW7*c_minor_bleed -> 0.49666957 | CG7: =dt*(CD7*dec_mi+CB7*dec_major_bleed+BW7*dec_minor_bleed+BV7*dec_tia) -> 3.3821042e-07 | CH7: =I7*BJ7+BX7+BS7-CA7+BT7-CB7+CC7 -> 2.0436833e-05 | CI7: =1-EXP(LN(1-E7)*dt) -> 0.0083541048 | CJ7: =J7*(1-CI7) -> 0.0060301047 | CK7: =(1-EXP(-r_stroke*F7*rr_asa_stroke*dt)) -> 0.0065772277 | CL7: =(1-EXP(-r_ich*rr_asa_ich*dt)) -> 0.0010235777 | CM7: =(1-EXP(-r_mb*rr_asa_mb*dt)) -> 0.0095180967 | CN7: =(1-EXP(-r_mi*rr_asa_mi*dt)) -> 0.0021341352 | CO7: =(1-EXP(-r_tia*rr_asa_tia*dt)) -> 0.0031276457 | CP7: =(1-EXP(-r_minor*rr_asa_minor*dt)) -> 0.027818195 | CQ7: =CJ7*CK7 -> 3.9661371e-05 | CR7: =CJ7*CL7 -> 6.1722805e-06 | CS7: =CJ7*CM7 -> 5.739512e-05 | CT7: =CJ7*CN7 -> 1.2869058e-05 | CU7: =CJ7*CO7 -> 1.8860031e-05 | CV7: =CJ7*CP7 -> 0.00016774663 | CW7: =CQ7*f_stroke_fatal -> 9.399745e-06 | CX7: =CQ7*(1-f_stroke_fatal)*f_stroke_major -> 1.0077122e-05 | CY7: =CQ7*(1-f_stroke_fatal)*(1-f_stroke_major) -> 2.0184505e-05 | CZ7: =CR7*(1-f_bleed_fatal) -> 5.653809e-06 | DA7: =CS7*(1-f_bleed_fatal) -> 5.2573929e-05 | DB7: =CT7*f_mi_fatal -> 1.5571561e-06 | DC7: =CT7-DB7 -> 1.1311902e-05 | DD7: =CJ7-CQ7-CR7-CS7-DB7 -> 0.0059253187 | DE7: =CW7*c_stroke_fatal+CX7*c_stroke_major+CY7*c_stroke_minor+CR7*c_ich+CS7*c_major_bleed+DB7*c_mi_fatal+DC7*c_mi_nonfatal+CU7*c_tia+CV7*c_minor_bleed -> 2.2773971 | DF7: =dt*(DC7*dec_mi+DA7*dec_major_bleed+CV7*dec_minor_bleed+CU7*dec_tia) -> 2.5935197e-06 | DG7: =J7*CI7+CW7+CR7-CZ7+CS7-DA7+DB7 -> 6.7097082e-05 | DH7: =AG7 -> 0.9620487 | DI7: =AB7+AC7+BF7+BA7+BB7+BC7+CY7+CZ7 -> 0.0046729289 | DJ7: =AA7+AZ7+BY7+CX7+CE7+BZ7+CA7+CB7 -> 0.0015926709 | DK7: =AD7+DD7+DA7 -> 0.01194239 | DL7: =K7+AJ7+BI7+CH7+DG7 -> 0.019743309 | DM7: =SUM(DH7:DL7) -> 1 | DN7: =dt*(G7*Apixaban!$H$2+(H7+I7+J7)*c_aspirin) -> 73.246602 | DO7: =dt*(H7*c_lt_minor_stroke+I7*c_lt_major_stroke) -> 11.646143 | DP7: =AH7+BG7+CF7+DE7 -> 214.26966 | DQ7: =DN7+DO7+DP7 -> 299.16241 | DR7: =dt*(G7*(u_af-dec_per_year_over_70*MAX(B7-ref_age,0))+H7*(u_minor_stroke-dec_per_year_over_70*MAX(B7-ref_age,0))+I7*(u_major_stroke-dec_per_year_over_70*MAX(B7-ref_age,0))+J7*(u_af-dec_per_year_over_70*MAX(B7-ref_age,0)))-AI7-BH7-CG7-DF7 -> 0.19998321 | DS7: =dt*(G7+H7+I7+J7) -> 0.24752786 | DT7: =DQ7*C7 -> 298.05095 | DU7: =DN7*C7 -> 72.974474 | DV7: =DP7*C7 -> 213.4736 | DW7: =DO7*C7 -> 11.602874 | DX7: =DR7*C7 -> 0.19924022 | DY7: =DS7*C7 -> 0.24660823 | DZ7: =T7+AS7+BR7+CQ7 -> 0.0032108674 | EA7: =U7+AT7+BS7+CR7 -> 0.00082981255 | EB7: =V7+AU7+BT7+CS7 -> 0.0065984853 | EC7: =G7*dt*C7 -> 0.24430319
A8: 2 | B8: =start_age+A8*dt -> 70.5 | C8: =(1+disc_rate)^-(A8*dt) -> 0.99258333 | D8: =IF(A8*dt>=wane_start,(1-wane_decay)^(A8*dt-wane_start),1) -> 1 | E8: =MIN(p_nonvasc_death*MIN(EXP(gomp_int+gomp_slope*INT(B8)),1)/qx_ref,0.999) -> 0.033 | F8: =rr_stroke_per_decade^((B8-ref_age)/10) -> 1.0204802 | G8: =DH7 -> 0.9620487 | H8: =DI7 -> 0.0046729289 | I8: =DJ7 -> 0.0015926709 | J8: =DK7 -> 0.01194239 | K8: =DL7 -> 0.019743309 | L8: =1-EXP(LN(1-E8)*dt) -> 0.0083541048 | M8: =G8*(1-L8) -> 0.95401165 | N8: =IF(Apixaban!$B$2=1,EXP(LN(or_apx_stroke)*D8)*(1-EXP(-r_stroke*F8*dt))/(1-(1-EXP(-r_stroke*F8*dt))+EXP(LN(or_apx_stroke)*D8)*(1-EXP(-r_stroke*F8*dt))),(1-EXP(-r_stroke*F8*dt))) -> 0.0032469143 | O8: =IF(Apixaban!$B$2=1,EXP(LN(or_apx_ich)*D8)*(1-EXP(-r_ich*dt))/(1-(1-EXP(-r_ich*dt))+EXP(LN(or_apx_ich)*D8)*(1-EXP(-r_ich*dt))),(1-EXP(-r_ich*dt))) -> 0.00084351325 | P8: =IF(Apixaban!$B$2=1,EXP(LN(or_apx_mb)*D8)*(1-EXP(-r_mb*dt))/(1-(1-EXP(-r_mb*dt))+EXP(LN(or_apx_mb)*D8)*(1-EXP(-r_mb*dt))),(1-EXP(-r_mb*dt))) -> 0.0066944691 | Q8: =IF(Apixaban!$B$2=1,EXP(LN(or_apx_mi)*D8)*(1-EXP(-r_mi*dt))/(1-(1-EXP(-r_mi*dt))+EXP(LN(or_apx_mi)*D8)*(1-EXP(-r_mi*dt))),(1-EXP(-r_mi*dt))) -> 0.0013232192 | R8: =(1-EXP(-r_tia*dt)) -> 0.0020060282 | S8: =(1-EXP(-r_minor*dt)) -> 0.043793769 | T8: =M8*N8 -> 0.0030975941 | U8: =M8*O8 -> 0.00080472146 | V8: =M8*P8 -> 0.0063866015 | W8: =M8*Q8 -> 0.0012623665 | X8: =M8*R8 -> 0.0019137742 | Y8: =M8*S8 -> 0.041779766 | Z8: =T8*f_stroke_fatal -> 0.0007341298 | AA8: =T8*(1-f_stroke_fatal)*f_stroke_major -> 0.00078703361 | AB8: =T8*(1-f_stroke_fatal)*(1-f_stroke_major) -> 0.0015764307 | AC8: =U8*(1-f_bleed_fatal) -> 0.00073712486 | AD8: =V8*(1-f_bleed_fatal) -> 0.0058501269 | AE8: =W8*f_mi_fatal -> 0.00015274634 | AF8: =W8-AE8 -> 0.0011096201 | AG8: =M8-T8-U8-V8-AE8 -> 0.94356998 | AH8: =Z8*c_stroke_fatal+AA8*c_stroke_major+AB8*c_stroke_minor+U8*c_ich+V8*c_major_bleed+AE8*c_mi_fatal+AF8*c_mi_nonfatal+X8*c_tia+Y8*c_minor_bleed -> 207.15167 | AI8: =dt*(AF8*dec_mi+AD8*dec_major_bleed+Y8*dec_minor_bleed+X8*dec_tia) -> 0.00035429247 | AJ8: =G8*L8+Z8+U8-AC8+V8-AD8+AE8 -> 0.0095280029 | AK8: =1-EXP(LN(1-E8)*hr_death_prior_stroke*dt) -> 0.019110191 | AL8: =H8*(1-AK8) -> 0.0045836283 | AM8: =(1-EXP(-r_stroke*F8*rr_stroke_prior*rr_asa_stroke*dt)) -> 0.014558589 | AN8: =(1-EXP(-r_ich*rr_asa_ich*dt)) -> 0.0010235777 | AO8: =(1-EXP(-r_mb*rr_asa_mb*dt)) -> 0.0095180967 | AP8: =(1-EXP(-r_mi*rr_asa_mi*dt)) -> 0.0021341352 | AQ8: =(1-EXP(-r_tia*rr_asa_tia*dt)) -> 0.0031276457 | AR8: =(1-EXP(-r_minor*rr_asa_minor*dt)) -> 0.027818195 | AS8: =AL8*AM8 -> 6.6731162e-05 | AT8: =AL8*AN8 -> 4.6916997e-06 | AU8: =AL8*AO8 -> 4.3627418e-05 | AV8: =AL8*AP8 -> 9.7820824e-06 | AW8: =AL8*AQ8 -> 1.4335965e-05 | AX8: =AL8*AR8 -> 0.00012750827 | AY8: =AS8*f_stroke_fatal_recur -> 2.4829998e-05 | AZ8: =AS8*(1-f_stroke_fatal_recur)*f_stroke_major -> 1.3953088e-05 | BA8: =AS8*(1-f_stroke_fatal_recur)*(1-f_stroke_major) -> 2.7948076e-05 | BB8: =AT8*(1-f_bleed_fatal) -> 4.2975969e-06 | BC8: =AU8*(1-f_bleed_fatal) -> 3.9962715e-05 | BD8: =AV8*f_mi_fatal -> 1.183632e-06 | BE8: =AV8-BD8 -> 8.5984504e-06 | BF8: =AL8-AS8-AT8-AU8-BD8 -> 0.0044673944 | BG8: =AY8*c_stroke_fatal+AZ8*c_stroke_major+BA8*c_stroke_minor+AT8*c_ich+AU8*c_major_bleed+BD8*c_mi_fatal+BE8*c_mi_nonfatal+AW8*c_tia+AX8*c_minor_bleed -> 2.9180776 | BH8: =dt*(BE8*dec_mi+BC8*dec_major_bleed+AX8*dec_minor_bleed+AW8*dec_tia) -> 1.971397e-06 | BI8: =H8*AK8+AY8+AT8-BB8+AU8-BC8+BD8 -> 0.000119373 | BJ8: =1-EXP(LN(1-E8)*hr_death_prior_stroke*dt) -> 0.019110191 | BK8: =I8*(1-BJ8) -> 0.0015622346 | BL8: =(1-EXP(-r_stroke*F8*rr_stroke_prior*rr_asa_stroke*dt)) -> 0.014558589 | BM8: =(1-EXP(-r_ich*rr_asa_ich*dt)) -> 0.0010235777 | BN8: =(1-EXP(-r_mb*rr_asa_mb*dt)) -> 0.0095180967 | BO8: =(1-EXP(-r_mi*rr_asa_mi*dt)) -> 0.0021341352 | BP8: =(1-EXP(-r_tia*rr_asa_tia*dt)) -> 0.0031276457 | BQ8: =(1-EXP(-r_minor*rr_asa_minor*dt)) -> 0.027818195 | BR8: =BK8*BL8 -> 2.2743932e-05 | BS8: =BK8*BM8 -> 1.5990685e-06 | BT8: =BK8*BN8 -> 1.48695e-05 | BU8: =BK8*BO8 -> 3.3340198e-06 | BV8: =BK8*BP8 -> 4.8861163e-06 | BW8: =BK8*BQ8 -> 4.3458547e-05 | BX8: =BR8*f_stroke_fatal_recur -> 8.4627896e-06 | BY8: =BR8*(1-f_stroke_fatal_recur)*f_stroke_major -> 4.7556204e-06 | BZ8: =BR8*(1-f_stroke_fatal_recur)*(1-f_stroke_major) -> 9.5255219e-06 | CA8: =BS8*(1-f_bleed_fatal) -> 1.4647467e-06 | CB8: =BT8*(1-f_bleed_fatal) -> 1.3620462e-05 | CC8: =BU8*f_mi_fatal -> 4.034164e-07 | CD8: =BU8-CC8 -> 2.9306034e-06 | CE8: =BK8-BR8-BS8-BT8-CC8 -> 0.0015226187 | CF8: =BX8*c_stroke_fatal+BY8*c_stroke_major+BZ8*c_stroke_minor+BS8*c_ich+BT8*c_major_bleed+CC8*c_mi_fatal+CD8*c_mi_nonfatal+BV8*c_tia+BW8*c_minor_bleed -> 0.99456621 | CG8: =dt*(CD8*dec_mi+CB8*dec_major_bleed+BW8*dec_minor_bleed+BV8*dec_tia) -> 6.7190976e-07 | CH8: =I8*BJ8+BX8+BS8-CA8+BT8-CB8+CC8 -> 4.068581e-05 | CI8: =1-EXP(LN(1-E8)*dt) -> 0.0083541048 | CJ8: =J8*(1-CI8) -> 0.011842622 | CK8: =(1-EXP(-r_stroke*F8*rr_asa_stroke*dt)) -> 0.0066440145 | CL8: =(1-EXP(-r_ich*rr_asa_ich*dt)) -> 0.0010235777 | CM8: =(1-EXP(-r_mb*rr_asa_mb*dt)) -> 0.0095180967 | CN8: =(1-EXP(-r_mi*rr_asa_mi*dt)) -> 0.0021341352 | CO8: =(1-EXP(-r_tia*rr_asa_tia*dt)) -> 0.0031276457 | CP8: =(1-EXP(-r_minor*rr_asa_minor*dt)) -> 0.027818195 | CQ8: =CJ8*CK8 -> 7.8682555e-05 | CR8: =CJ8*CL8 -> 1.2121844e-05 | CS8: =CJ8*CM8 -> 0.00011271922 | CT8: =CJ8*CN8 -> 2.5273757e-05 | CU8: =CJ8*CO8 -> 3.7039526e-05 | CV8: =CJ8*CP8 -> 0.00032944038 | CW8: =CQ8*f_stroke_fatal -> 1.8647765e-05 | CX8: =CQ8*(1-f_stroke_fatal)*f_stroke_major -> 1.9991585e-05 | CY8: =CQ8*(1-f_stroke_fatal)*(1-f_stroke_major) -> 4.0043204e-05 | CZ8: =CR8*(1-f_bleed_fatal) -> 1.1103609e-05 | DA8: =CS8*(1-f_bleed_fatal) -> 0.00010325081 | DB8: =CT8*f_mi_fatal -> 3.0581246e-06 | DC8: =CT8-DB8 -> 2.2215632e-05 | DD8: =CJ8-CQ8-CR8-CS8-DB8 -> 0.011636041 | DE8: =CW8*c_stroke_fatal+CX8*c_stroke_major+CY8*c_stroke_minor+CR8*c_ich+CS8*c_major_bleed+DB8*c_mi_fatal+DC8*c_mi_nonfatal+CU8*c_tia+CV8*c_minor_bleed -> 4.5018408 | DF8: =dt*(DC8*dec_mi+DA8*dec_major_bleed+CV8*dec_minor_bleed+CU8*dec_tia) -> 5.0934562e-06 | DG8: =J8*CI8+CW8+CR8-CZ8+CS8-DA8+DB8 -> 0.00013196052 | DH8: =AG8 -> 0.94356998 | DI8: =AB8+AC8+BF8+BA8+BB8+BC8+CY8+CZ8 -> 0.0069043052 | DJ8: =AA8+AZ8+BY8+CX8+CE8+BZ8+CA8+CB8 -> 0.0023729633 | DK8: =AD8+DD8+DA8 -> 0.017589418 | DL8: =K8+AJ8+BI8+CH8+DG8 -> 0.029563331 | DM8: =SUM(DH8:DL8) -> 1 | DN8: =dt*(G8*Apixaban!$H$2+(H8+I8+J8)*c_aspirin) -> 71.931198 | DO8: =dt*(H8*c_lt_minor_stroke+I8*c_lt_major_stroke) -> 23.030484 | DP8: =AH8+BG8+CF8+DE8 -> 215.56616 | DQ8: =DN8+DO8+DP8 -> 310.52784 | DR8: =dt*(G8*(u_af-dec_per_year_over_70*MAX(B8-ref_age,0))+H8*(u_minor_stroke-dec_per_year_over_70*MAX(B8-ref_age,0))+I8*(u_major_stroke-dec_per_year_over_70*MAX(B8-ref_age,0))+J8*(u_af-dec_per_year_over_70*MAX(B8-ref_age,0)))-AI8-BH8-CG8-DF8 -> 0.19784424 | DS8: =dt*(G8+H8+I8+J8) -> 0.24506417 | DT8: =DQ8*C8 -> 308.22476 | DU8: =DN8*C8 -> 71.397709 | DV8: =DP8*C8 -> 213.96738 | DW8: =DO8*C8 -> 22.859674 | DX8: =DR8*C8 -> 0.19637689 | DY8: =DS8*C8 -> 0.24324661 | DZ8: =T8+AS8+BR8+CQ8 -> 0.0032657517 | EA8: =U8+AT8+BS8+CR8 -> 0.00082313408 | EB8: =V8+AU8+BT8+CS8 -> 0.0065578176 | EC8: =G8*dt*C8 -> 0.23872838
A9: 3 | B9: =start_age+A9*dt -> 70.75 | C9: =(1+disc_rate)^-(A9*dt) -> 0.98889565 | D9: =IF(A9*dt>=wane_start,(1-wane_decay)^(A9*dt-wane_start),1) -> 1 | E9: =MIN(p_nonvasc_death*MIN(EXP(gomp_int+gomp_slope*INT(B9)),1)/qx_ref,0.999) -> 0.033 | F9: =rr_stroke_per_decade^((B9-ref_age)/10) -> 1.030877 | G9: =DH8 -> 0.94356998 | H9: =DI8 -> 0.0069043052 | I9: =DJ8 -> 0.0023729633 | J9: =DK8 -> 0.017589418 | K9: =DL8 -> 0.029563331 | L9: =1-EXP(LN(1-E9)*dt) -> 0.0083541048 | M9: =G9*(1-L9) -> 0.9356873 | N9: =IF(Apixaban!$B$2=1,EXP(LN(or_apx_stroke)*D9)*(1-EXP(-r_stroke*F9*dt))/(1-(1-EXP(-r_stroke*F9*dt))+EXP(LN(or_apx_stroke)*D9)*(1-EXP(-r_stroke*F9*dt))),(1-EXP(-r_stroke*F9*dt))) -> 0.0032799545 | O9: =IF(Apixaban!$B$2=1,EXP(LN(or_apx_ich)*D9)*(1-EXP(-r_ich*dt))/(1-(1-EXP(-r_ich*dt))+EXP(LN(or_apx_ich)*D9)*(1-EXP(-r_ich*dt))),(1-EXP(-r_ich*dt))) -> 0.00084351325 | P9: =IF(Apixaban!$B$2=1,EXP(LN(or_apx_mb)*D9)*(1-EXP(-r_mb*dt))/(1-(1-EXP(-r_mb*dt))+EXP(LN(or_apx_mb)*D9)*(1-EXP(-r_mb*dt))),(1-EXP(-r_mb*dt))) -> 0.0066944691 | Q9: =IF(Apixaban!$B$2=1,EXP(LN(or_apx_mi)*D9)*(1-EXP(-r_mi*dt))/(1-(1-EXP(-r_mi*dt))+EXP(LN(or_apx_mi)*D9)*(1-EXP(-r_mi*dt))),(1-EXP(-r_mi*dt))) -> 0.0013232192 | R9: =(1-EXP(-r_tia*dt)) -> 0.0020060282 | S9: =(1-EXP(-r_minor*dt)) -> 0.043793769 | T9: =M9*N9 -> 0.0030690118 | U9: =M9*O9 -> 0.00078926463 | V9: =M9*P9 -> 0.0062639297 | W9: =M9*Q9 -> 0.0012381194 | X9: =M9*R9 -> 0.0018770151 | Y9: =M9*S9 -> 0.040977274 | Z9: =T9*f_stroke_fatal -> 0.0007273558 | AA9: =T9*(1-f_stroke_fatal)*f_stroke_major -> 0.00077977145 | AB9: =T9*(1-f_stroke_fatal)*(1-f_stroke_major) -> 0.0015618846 | AC9: =U9*(1-f_bleed_fatal) -> 0.00072296641 | AD9: =V9*(1-f_bleed_fatal) -> 0.0057377596 | AE9: =W9*f_mi_fatal -> 0.00014981244 | AF9: =W9-AE9 -> 0.0010883069 | AG9: =M9-T9-U9-V9-AE9 -> 0.92541528 | AH9: =Z9*c_stroke_fatal+AA9*c_stroke_major+AB9*c_stroke_minor+U9*c_ich+V9*c_major_bleed+AE9*c_mi_fatal+AF9*c_mi_nonfatal+X9*c_tia+Y9*c_minor_bleed -> 204.31502 | AI9: =dt*(AF9*dec_mi+AD9*dec_major_bleed+Y9*dec_minor_bleed+X9*dec_tia) -> 0.00034748734 | AJ9: =G9*L9+Z9+U9-AC9+V9-AD9+AE9 -> 0.0093523191 | AK9: =1-EXP(LN(1-E9)*hr_death_prior_stroke*dt) -> 0.019110191 | AL9: =H9*(1-AK9) -> 0.0067723626 | AM9: =(1-EXP(-r_stroke*F9*rr_stroke_prior*rr_asa_stroke*dt)) -> 0.014705819 | AN9: =(1-EXP(-r_ich*rr_asa_ich*dt)) -> 0.0010235777 | AO9: =(1-EXP(-r_mb*rr_asa_mb*dt)) -> 0.0095180967 | AP9: =(1-EXP(-r_mi*rr_asa_mi*dt)) -> 0.0021341352 | AQ9: =(1-EXP(-r_tia*rr_asa_tia*dt)) -> 0.0031276457 | AR9: =(1-EXP(-r_minor*rr_asa_minor*dt)) -> 0.027818195 | AS9: =AL9*AM9 -> 9.9593136e-05 | AT9: =AL9*AN9 -> 6.9320392e-06 | AU9: =AL9*AO9 -> 6.4460002e-05 | AV9: =AL9*AP9 -> 1.4453137e-05 | AW9: =AL9*AQ9 -> 2.118155e-05 | AX9: =AL9*AR9 -> 0.0001883949 | AY9: =AS9*f_stroke_fatal_recur -> 3.705761e-05 | AZ9: =AS9*(1-f_stroke_fatal_recur)*f_stroke_major -> 2.082433e-05 | BA9: =AS9*(1-f_stroke_fatal_recur)*(1-f_stroke_major) -> 4.1711196e-05 | BB9: =AT9*(1-f_bleed_fatal) -> 6.3497479e-06 | BC9: =AU9*(1-f_bleed_fatal) -> 5.9045362e-05 | BD9: =AV9*f_mi_fatal -> 1.7488296e-06 | BE9: =AV9-BD9 -> 1.2704308e-05 | BF9: =AL9-AS9-AT9-AU9-BD9 -> 0.0065996286 | BG9: =AY9*c_stroke_fatal+AZ9*c_stroke_major+BA9*c_stroke_minor+AT9*c_ich+AU9*c_major_bleed+BD9*c_mi_fatal+BE9*c_mi_nonfatal+AW9*c_tia+AX9*c_minor_bleed -> 4.3458718 | BH9: =dt*(BE9*dec_mi+BC9*dec_major_bleed+AX9*dec_minor_bleed+AW9*dec_tia) -> 2.9127613e-06 | BI9: =H9*AK9+AY9+AT9-BB9+AU9-BC9+BD9 -> 0.00017674596 | BJ9: =1-EXP(LN(1-E9)*hr_death_prior_stroke*dt) -> 0.019110191 | BK9: =I9*(1-BJ9) -> 0.0023276155 | BL9: =(1-EXP(-r_stroke*F9*rr_stroke_prior*rr_asa_stroke*dt)) -> 0.014705819 | BM9: =(1-EXP(-r_ich*rr_asa_ich*dt)) -> 0.0010235777 | BN9: =(1-EXP(-r_mb*rr_asa_mb*dt)) -> 0.0095180967 | BO9: =(1-EXP(-r_mi*rr_asa_mi*dt)) -> 0.0021341352 | BP9: =(1-EXP(-r_tia*rr_asa_tia*dt)) -> 0.0031276457 | BQ9: =(1-EXP(-r_minor*rr_asa_minor*dt)) -> 0.027818195 | BR9: =BK9*BL9 -> 3.4229492e-05 | BS9: =BK9*BM9 -> 2.3824953e-06 | BT9: =BK9*BN9 -> 2.215447e-05 | BU9: =BK9*BO9 -> 4.9674462e-06 | BV9: =BK9*BP9 -> 7.2799567e-06 | BW9: =BK9*BQ9 -> 6.4750063e-05 | BX9: =BR9*f_stroke_fatal_recur -> 1.2736452e-05 | BY9: =BR9*(1-f_stroke_fatal_recur)*f_stroke_major -> 7.1571824e-06 | BZ9: =BR9*(1-f_stroke_fatal_recur)*(1-f_stroke_major) -> 1.4335858e-05 | CA9: =BS9*(1-f_bleed_fatal) -> 2.1823657e-06 | CB9: =BT9*(1-f_bleed_fatal) -> 2.0293494e-05 | CC9: =BU9*f_mi_fatal -> 6.0106099e-07 | CD9: =BU9-CC9 -> 4.3663852e-06 | CE9: =BK9-BR9-BS9-BT9-CC9 -> 0.002268248 | CF9: =BX9*c_stroke_fatal+BY9*c_stroke_major+BZ9*c_stroke_minor+BS9*c_ich+BT9*c_major_bleed+CC9*c_mi_fatal+CD9*c_mi_nonfatal+BV9*c_tia+BW9*c_minor_bleed -> 1.493647 | CG9: =dt*(CD9*dec_mi+CB9*dec_major_bleed+BW9*dec_minor_bleed+BV9*dec_tia) -> 1.0010965e-06 | CH9: =I9*BJ9+BX9+BS9-CA9+BT9-CB9+CC9 -> 6.0746399e-05 | CI9: =1-EXP(LN(1-E9)*dt) -> 0.0083541048 | CJ9: =J9*(1-CI9) -> 0.017442474 | CK9: =(1-EXP(-r_stroke*F9*rr_asa_stroke*dt)) -> 0.0067114773 | CL9: =(1-EXP(-r_ich*rr_asa_ich*dt)) -> 0.0010235777 | CM9: =(1-EXP(-r_mb*rr_asa_mb*dt)) -> 0.0095180967 | CN9: =(1-EXP(-r_mi*rr_asa_mi*dt)) -> 0.0021341352 | CO9: =(1-EXP(-r_tia*rr_asa_tia*dt)) -> 0.0031276457 | CP9: =(1-EXP(-r_minor*rr_asa_minor*dt)) -> 0.027818195 | CQ9: =CJ9*CK9 -> 0.00011706477 | CR9: =CJ9*CL9 -> 1.7853728e-05 | CS9: =CJ9*CM9 -> 0.00016601916 | CT9: =CJ9*CN9 -> 3.7224598e-05 | CU9: =CJ9*CO9 -> 5.4553879e-05 | CV9: =CJ9*CP9 -> 0.00048521816 | CW9: =CQ9*f_stroke_fatal -> 2.7744351e-05 | CX9: =CQ9*(1-f_stroke_fatal)*f_stroke_major -> 2.97437e-05 | CY9: =CQ9*(1-f_stroke_fatal)*(1-f_stroke_major) -> 5.957672e-05 | CZ9: =CR9*(1-f_bleed_fatal) -> 1.6354014e-05 | DA9: =CS9*(1-f_bleed_fatal) -> 0.00015207355 | DB9: =CT9*f_mi_fatal -> 4.5041764e-06 | DC9: =CT9-DB9 -> 3.2720422e-05 | DD9: =CJ9-CQ9-CR9-CS9-DB9 -> 0.017137033 | DE9: =CW9*c_stroke_fatal+CX9*c_stroke_major+CY9*c_stroke_minor+CR9*c_ich+CS9*c_major_bleed+DB9*c_mi_fatal+DC9*c_mi_nonfatal+CU9*c_tia+CV9*c_minor_bleed -> 6.6740391 | DF9: =dt*(DC9*dec_mi+DA9*dec_major_bleed+CV9*dec_minor_bleed+CU9*dec_tia) -> 7.5019262e-06 | DG9: =J9*CI9+CW9+CR9-CZ9+CS9-DA9+DB9 -> 0.00019463769 | DH9: =AG9 -> 0.92541528 | DI9: =AB9+AC9+BF9+BA9+BB9+BC9+CY9+CZ9 -> 0.0090675166 | DJ9: =AA9+AZ9+BY9+CX9+CE9+BZ9+CA9+CB9 -> 0.0031425564 | DK9: =AD9+DD9+DA9 -> 0.023026866 | DL9: =K9+AJ9+BI9+CH9+DG9 -> 0.03934778 | DM9: =SUM(DH9:DL9) -> 1 | DN9: =dt*(G9*Apixaban!$H$2+(H9+I9+J9)*c_aspirin) -> 70.63749 | DO9: =dt*(H9*c_lt_minor_stroke+I9*c_lt_major_stroke) -> 34.156897 | DP9: =AH9+BG9+CF9+DE9 -> 216.82858 | DQ9: =DN9+DO9+DP9 -> 321.62297 | DR9: =dt*(G9*(u_af-dec_per_year_over_70*MAX(B9-ref_age,0))+H9*(u_minor_stroke-dec_per_year_over_70*MAX(B9-ref_age,0))+I9*(u_major_stroke-dec_per_year_over_70*MAX(B9-ref_age,0))+J9*(u_af-dec_per_year_over_70*MAX(B9-ref_age,0)))-AI9-BH9-CG9-DF9 -> 0.19571498 | DS9: =dt*(G9+H9+I9+J9) -> 0.24260917 | DT9: =DQ9*C9 -> 318.05155 | DU9: =DN9*C9 -> 69.853106 | DV9: =DP9*C9 -> 214.42084 | DW9: =DO9*C9 -> 33.777607 | DX9: =DR9*C9 -> 0.19354169 | DY9: =DS9*C9 -> 0.23991515 | DZ9: =T9+AS9+BR9+CQ9 -> 0.0033198992 | EA9: =U9+AT9+BS9+CR9 -> 0.0008164329 | EB9: =V9+AU9+BT9+CS9 -> 0.0065165633 | EC9: =G9*dt*C9 -> 0.23327306
